Workbook

Sheet Summary
A1: Drake Entry Tracker - Summary
A2: Built 2026-09-23 22:38 from the audit log. Counts are formulas that read each client tab. Resolve every item on the Exceptions tab before sign-off.
A4: Prepared by | B4: QA
A5: Reviewed by
A6: Review date
A8: Client | B8: Name | C8: Form | D8: Documents | E8: Fields Entered | F8: Open Mismatches | G8: Incomplete | H8: Not Read Back | I8: Corrections | J8: Tie-Out | K8: Status | L8: Reviewer | M8: Date Reviewed
A9: ***-**-6789 | B9: Sam Rivera | C9: Form W-2 - Wage and Tax Statement | D9: =COUNTIFS('6789 Sam Rivera'!H:H,"W2",'6789 Sam Rivera'!I:I,"INSTANCE") -> 2 | E9: =COUNTIFS('6789 Sam Rivera'!H:H,"W2",'6789 Sam Rivera'!I:I,"FIELD") -> 35 | F9: =COUNTIFS('6789 Sam Rivera'!H:H,"W2",'6789 Sam Rivera'!D:D,"MISMATCH") -> 0 | G9: =COUNTIFS('6789 Sam Rivera'!H:H,"W2",'6789 Sam Rivera'!J:J,"Incomplete") -> 0 | H9: =COUNTIFS('6789 Sam Rivera'!H:H,"W2",'6789 Sam Rivera'!D:D,"Not read back") -> 3 | I9: =COUNTIFS(Corrections!B:B,A9,Corrections!C:C,"W2") -> 0 | J9: Not confirmed | K9: =IF(F9>0,"Open mismatches",IF(G9>0,"Incomplete entries",IF(J9="DID NOT AGREE","Tie-out failed",IF(J9="Not confirmed","Confirm tie-out",IF(H9>0,"Ready - check screenshots","Ready for review"))))) -> Confirm tie-out
A10: ***-**-4321 | B10: Lee Chen | C10: Form W-2 - Wage and Tax Statement | D10: =COUNTIFS('4321 Lee Chen'!H:H,"W2",'4321 Lee Chen'!I:I,"INSTANCE") -> 1 | E10: =COUNTIFS('4321 Lee Chen'!H:H,"W2",'4321 Lee Chen'!I:I,"FIELD") -> 15 | F10: =COUNTIFS('4321 Lee Chen'!H:H,"W2",'4321 Lee Chen'!D:D,"MISMATCH") -> 0 | G10: =COUNTIFS('4321 Lee Chen'!H:H,"W2",'4321 Lee Chen'!J:J,"Incomplete") -> 0 | H10: =COUNTIFS('4321 Lee Chen'!H:H,"W2",'4321 Lee Chen'!D:D,"Not read back") -> 1 | I10: =COUNTIFS(Corrections!B:B,A10,Corrections!C:C,"W2") -> 9 | J10: Not confirmed | K10: =IF(F10>0,"Open mismatches",IF(G10>0,"Incomplete entries",IF(J10="DID NOT AGREE","Tie-out failed",IF(J10="Not confirmed","Confirm tie-out",IF(H10>0,"Ready - check screenshots","Ready for review"))))) -> Confirm tie-out
A11: ***-**-2222 | B11: Kim Patel | C11: Form W-2 - Wage and Tax Statement | D11: =COUNTIFS('2222 Kim Patel'!H:H,"W2",'2222 Kim Patel'!I:I,"INSTANCE") -> 1 | E11: =COUNTIFS('2222 Kim Patel'!H:H,"W2",'2222 Kim Patel'!I:I,"FIELD") -> 12 | F11: =COUNTIFS('2222 Kim Patel'!H:H,"W2",'2222 Kim Patel'!D:D,"MISMATCH") -> 0 | G11: =COUNTIFS('2222 Kim Patel'!H:H,"W2",'2222 Kim Patel'!J:J,"Incomplete") -> 0 | H11: =COUNTIFS('2222 Kim Patel'!H:H,"W2",'2222 Kim Patel'!D:D,"Not read back") -> 1 | I11: =COUNTIFS(Corrections!B:B,A11,Corrections!C:C,"W2") -> 0 | J11: Not confirmed | K11: =IF(F11>0,"Open mismatches",IF(G11>0,"Incomplete entries",IF(J11="DID NOT AGREE","Tie-out failed",IF(J11="Not confirmed","Confirm tie-out",IF(H11>0,"Ready - check screenshots","Ready for review"))))) -> Confirm tie-out

Sheet Exceptions
A1: Exceptions
A2: Items needing attention before sign-off. High = must resolve; Medium = review; Info = confirm against the screenshot.
A4: Severity | B4: Client | C4: Form | D4: Document | E4: Field / Item | F4: Issue | G4: Source | H4: Drake | I4: Note | J4: When | K4: Resolved By | L4: Resolution
A5: Medium | B5: ***-**-6789 | C5: W2 | E5: Tie-out | F5: Tie-out not confirmed yet
A6: Medium | B6: ***-**-4321 | C6: W2 | E6: Tie-out | F6: Tie-out not confirmed yet
A7: Medium | B7: ***-**-2222 | C7: W2 | E7: Tie-out | F7: Tie-out not confirmed yet
A8: Info | B8: ***-**-6789 | C8: W2 | D8: W-2 #1 | E8: TS - Taxpayer / Spouse | F8: Not read back - check screenshot | G8: T | H8: T | J8: 2026-09-23 22:38:50
A9: Info | B9: ***-**-6789 | C9: W2 | D9: W-2 #1 | E9: 13 - Retirement plan | F9: Not read back - check screenshot | G9: X | H9: X | J9: 2026-09-23 22:38:50
A10: Info | B10: ***-**-6789 | C10: W2 | D10: W-2 #2 | E10: TS - Taxpayer / Spouse | F10: Not read back - check screenshot | G10: S | H10: S | J10: 2026-09-23 22:38:50
A11: Info | B11: ***-**-4321 | C11: W2 | D11: W-2 #1 | E11: TS - Taxpayer / Spouse | F11: Not read back - check screenshot | G11: T | H11: T | J11: 2026-09-23 22:38:56
A12: Info | B12: ***-**-2222 | C12: W2 | D12: W-2 #1 | E12: TS - Taxpayer / Spouse | F12: Not read back - check screenshot | G12: T | H12: T | J12: 2026-09-23 22:38:54

Sheet Corrections
A1: Corrections
A2: Every change made to Drake after the original entry. 'Before' and 'After' are read from the Drake screen.
A4: When | B4: Client | C4: Form | D4: Document # | E4: Field | F4: Before (Drake) | G4: After (Drake) | H4: Source Value | I4: Reason | J4: Result | K4: By | L4: Run ID
A5: 2026-09-23 22:38:53 | B5: ***-**-4321 | C5: W2 | D5: 1 | E5: 2 - Federal income tax withheld | F5: 99999 | G5: 6100 | H5: 6100 | I5: Keying error | J5: Fixed | K5: QA | L5: 20260923-223853
A6: 2026-09-23 22:38:53 | B6: ***-**-4321 | C6: W2 | D6: 1 | E6: 3 - Social security wages | G6: 61000 | H6: 61000 | I6: Keying error | J6: Fixed | K6: QA | L6: 20260923-223853
A7: 2026-09-23 22:38:53 | B7: ***-**-4321 | C7: W2 | D7: 1 | E7: 4 - Social security tax withheld | G7: 3782 | H7: 3782 | I7: Keying error | J7: Fixed | K7: QA | L7: 20260923-223853
A8: 2026-09-23 22:38:53 | B8: ***-**-4321 | C8: W2 | D8: 1 | E8: 5 - Medicare wages and tips | G8: 61000 | H8: 61000 | I8: Keying error | J8: Fixed | K8: QA | L8: 20260923-223853
A9: 2026-09-23 22:38:53 | B9: ***-**-4321 | C9: W2 | D9: 1 | E9: 6 - Medicare tax withheld | G9: 884.50 | H9: 884.50 | I9: Keying error | J9: Fixed | K9: QA | L9: 20260923-223853
A10: 2026-09-23 22:38:53 | B10: ***-**-4321 | C10: W2 | D10: 1 | E10: 15 - State | G10: CO | H10: CO | I10: Keying error | J10: Fixed | K10: QA | L10: 20260923-223853
A11: 2026-09-23 22:38:53 | B11: ***-**-4321 | C11: W2 | D11: 1 | E11: 16 - State wages, tips, etc. | G11: 61000 | H11: 61000 | I11: Keying error | J11: Fixed | K11: QA | L11: 20260923-223853
A12: 2026-09-23 22:38:53 | B12: ***-**-4321 | C12: W2 | D12: 1 | E12: 17 - State income tax | G12: 2684 | H12: 2684 | I12: Keying error | J12: Fixed | K12: QA | L12: 20260923-223853
A13: 2026-09-23 22:38:55 | B13: ***-**-4321 | C13: W2 | D13: 1 | E13: b - Employer identification number (EIN) | F13: 201112223 | G13: 201112299 | H13: 20-1112299 | I13: Keying error | J13: Fixed | K13: QA | L13: 20260923-223855

Sheet Tie-Out
A1: Tie-Out
A2: Totals from the input workbook to agree to the return in Drake. Latest confirmation per client/form/total (full history in the audit log).
A4: Client | B4: Name | C4: Form | D4: Total | E4: Amount per Source | F4: Ties To | G4: Agrees? | H4: Confirmed By | I4: When
A5: ***-**-6789 | B5: Sam Rivera | C5: W2 | D5: Total Box 1 wages | E5: 90500 | F5: Form 1040, line 1a | G5: Not checked | H5: QA | I5: 2026-09-23 22:38:50
A6: ***-**-6789 | B6: Sam Rivera | C6: W2 | D6: Total Box 2 federal withholding | E6: 7700 | F6: Form 1040, line 25a | G6: Not checked | H6: QA | I6: 2026-09-23 22:38:50
A7: ***-**-6789 | B7: Sam Rivera | C7: W2 | D7: Taxpayer Box 1 | E7: 52000 | F7: W-2 summary | G7: Not checked | H7: QA | I7: 2026-09-23 22:38:50
A8: ***-**-6789 | B8: Sam Rivera | C8: W2 | D8: Spouse Box 1 | E8: 38500 | F8: W-2 summary | G8: Not checked | H8: QA | I8: 2026-09-23 22:38:50
A9: ***-**-6789 | B9: Sam Rivera | C9: W2 | D9: Total Box 17 CO withholding | E9: 3982 | F9: CO return withholding | G9: Not checked | H9: QA | I9: 2026-09-23 22:38:50
A10: ***-**-4321 | B10: Lee Chen | C10: W2 | D10: Total Box 1 wages | E10: 61000 | F10: Form 1040, line 1a | G10: Not checked | H10: QA | I10: 2026-09-23 22:38:56
A11: ***-**-4321 | B11: Lee Chen | C11: W2 | D11: Total Box 2 federal withholding | E11: 6100 | F11: Form 1040, line 25a | G11: Not checked | H11: QA | I11: 2026-09-23 22:38:56
A12: ***-**-4321 | B12: Lee Chen | C12: W2 | D12: Total Box 17 CO withholding | E12: 2684 | F12: CO return withholding | G12: Not checked | H12: QA | I12: 2026-09-23 22:38:56
A13: ***-**-2222 | B13: Kim Patel | C13: W2 | D13: Total Box 1 wages | E13: 47000 | F13: Form 1040, line 1a | G13: Not checked | H13: QA | I13: 2026-09-23 22:38:54
A14: ***-**-2222 | B14: Kim Patel | C14: W2 | D14: Total Box 2 federal withholding | E14: 3900 | F14: Form 1040, line 25a | G14: Not checked | H14: QA | I14: 2026-09-23 22:38:54

Sheet Run Log
A1: Run Log
A2: Every run of the tool. The input SHA-256 proves which version of the input workbook was used.
A4: Run ID | B4: Mode | C4: Started | D4: Ended | E4: Status | F4: Summary | G4: Initials | H4: Windows User | I4: Machine | J4: Input File | K4: Input SHA-256 | L4: Tool Version
A5: 20260923-223850 | B5: enter | C5: 2026-09-23 22:38:50 | D5: 2026-09-23 22:38:50 | E5: stopped | F5: 1 mismatches | G5: QA | H5: root | I5: vm | J5: Client_Input.xlsx | K5: f4900036b54ccd0c4e61d02d | L5: 2.0.0
A6: 20260923-223851 | B6: enter | C6: 2026-09-23 22:38:51 | D6: 2026-09-23 22:38:51 | E6: completed | G6: QA | H6: root | I6: vm | J6: Client_Input.xlsx | K6: f4900036b54ccd0c4e61d02d | L6: 2.0.0
A7: 20260923-223852 | B7: verify | C7: 2026-09-23 22:38:52 | D7: 2026-09-23 22:38:52 | E7: completed | F7: 1 verified, 8 mismatches | G7: QA | H7: root | I7: vm | J7: Client_Input.xlsx | K7: f4900036b54ccd0c4e61d02d | L7: 2.0.0
A8: 20260923-223853 | B8: verify | C8: 2026-09-23 22:38:53 | D8: 2026-09-23 22:38:53 | E8: completed | F8: 1 verified | G8: QA | H8: root | I8: vm | J8: Client_Input.xlsx | K8: f4900036b54ccd0c4e61d02d | L8: 2.0.0
A9: 20260923-223854 | B9: enter | C9: 2026-09-23 22:38:54 | D9: 2026-09-23 22:38:54 | E9: completed | F9: 1 entered | G9: QA | H9: root | I9: vm | J9: Client_Input.xlsx | K9: 18c2c4a1d5953627f852051b | L9: 2.0.0
A10: 20260923-223855 | B10: correct | C10: 2026-09-23 22:38:55 | D10: 2026-09-23 22:38:55 | E10: completed | F10: 1 verified, 1 corrected, 1 mismatches | G10: QA | H10: root | I10: vm | J10: Client_Input.xlsx | K10: ddd80cfc99528d64b441ad3c | L10: 2.0.0
A11: 20260923-223856 | B11: verify | C11: 2026-09-23 22:38:56 | D11: 2026-09-23 22:38:56 | E11: completed | F11: 1 verified | G11: QA | H11: root | I11: vm | J11: Client_Input.xlsx | K11: ddd80cfc99528d64b441ad3c | L11: 2.0.0

Sheet Audit Integrity
A1: Audit Integrity
A2: The audit log is append-only and hash-chained: each entry includes the SHA-256 of the entry before it, so any edit, deletion or reordering is detected.
A4: Audit log | B4: audit_log.jsonl
A5: Chain check | B5: PASSED - no entries altered, removed or reordered
A6: Entries checked | B6: 408
A7: First entry | B7: 2026-09-23 22:38:50
A8: Last entry | B8: 2026-09-23 22:38:56
A9: Last entry hash | B9: c7055bff26c826c2d118f37cc05c382c2f6898790ddcabf8e65ab539e08a39c0
A10: Checked at | B10: 2026-09-23 22:38:58
A11: Re-check anytime | B11: python run.py audit-verify
A12: Retention | B12: Keep logs/, evidence/ and tracking/ with the client file per your firm's retention policy.

Sheet 6789 Sam Rivera
A1: Sam Rivera (***-**-6789) - Drake Entry Tracker
A2: Source Document = input workbook value. Entered in Drake = value read back from the Drake screen (typed value where the field can't be read back). Reviewer: initial each line or each document.
A4: FORM W-2 - WAGE AND TAX STATEMENT
A6: W-2 #1 - 84-1234567 | Front Range Hotels LLC - entered 2026-09-23 22:38:50 by QA - Complete - some fields not read back | H6: W2 | I6: INSTANCE | J6: Complete - some fields not read back
A7: Evidence: screenshot 223850_6789_W2_1.png (SHA-256 dac9b8759818a663...)
A8: Drake Screen Field | B8: Source Document (W-2) | C8: Entered in Drake | D8: Verified | E8: Last Action | F8: Reviewer | G8: Notes
A9: TS - Taxpayer / Spouse | B9: T | C9: T | D9: Not read back | E9: Entered 2026-09-23 22:38:50 QA | G9: Can't be read back; check the screenshot. | H9: W2 | I9: FIELD
A10: b - Employer identification number (EIN) | B10: 84-1234567 | C10: 841234567 | D10: OK | E10: Entered 2026-09-23 22:38:50 QA | H10: W2 | I10: FIELD
A11: c - Employer name | B11: Front Range Hotels LLC | C11: Front Range Hotels LLC | D11: OK | E11: Entered 2026-09-23 22:38:50 QA | H11: W2 | I11: FIELD
A12: c - Employer street address | B12: 1600 Broadway | C12: 1600 Broadway | D12: OK | E12: Entered 2026-09-23 22:38:50 QA | H12: W2 | I12: FIELD
A13: c - Employer city | B13: Denver | C13: Denver | D13: OK | E13: Entered 2026-09-23 22:38:50 QA | H13: W2 | I13: FIELD
A14: c - Employer state | B14: CO | C14: CO | D14: OK | E14: Entered 2026-09-23 22:38:50 QA | H14: W2 | I14: FIELD
A15: c - Employer ZIP | B15: 80202 | C15: 80202 | D15: OK | E15: Entered 2026-09-23 22:38:50 QA | H15: W2 | I15: FIELD
A16: 1 - Wages, tips, other compensation | B16: 52,000.00 | C16: 52000 | D16: OK | E16: Entered 2026-09-23 22:38:50 QA | H16: W2 | I16: FIELD
A17: 2 - Federal income tax withheld | B17: 4800 | C17: 4800 | D17: OK | E17: Entered 2026-09-23 22:38:50 QA | H17: W2 | I17: FIELD
A18: 3 - Social security wages | B18: 55000 | C18: 55000 | D18: OK | E18: Entered 2026-09-23 22:38:50 QA | H18: W2 | I18: FIELD
A19: 4 - Social security tax withheld | B19: 3400 | C19: 3400 | D19: OK | E19: Entered 2026-09-23 22:38:50 QA | H19: W2 | I19: FIELD
A20: 5 - Medicare wages and tips | B20: 55000 | C20: 55000 | D20: OK | E20: Entered 2026-09-23 22:38:50 QA | H20: W2 | I20: FIELD
A21: 6 - Medicare tax withheld | B21: 797.50 | C21: 797.50 | D21: OK | E21: Entered 2026-09-23 22:38:50 QA | H21: W2 | I21: FIELD
... A23: 12a - Amount | B23: 3000 | C23: 3000 | D23: OK | E23: Entered 2026-09-23 22:38:50 QA | H23: W2 | I23: FIELD
A24: 13 - Retirement plan | B24: X | C24: X | D24: Not read back | E24: Entered 2026-09-23 22:38:50 QA | G24: Can't be read back; check the screenshot. | H24: W2 | I24: FIELD
A25: 15 - State | B25: CO | C25: CO | D25: OK | E25: Entered 2026-09-23 22:38:50 QA | H25: W2 | I25: FIELD
A26: 15 - Employer's state ID number | B26: 12345678 | C26: 12345678 | D26: OK | E26: Entered 2026-09-23 22:38:50 QA | H26: W2 | I26: FIELD
A27: 16 - State wages, tips, etc. | B27: 52000 | C27: 52000 | D27: OK | E27: Entered 2026-09-23 22:38:50 QA | H27: W2 | I27: FIELD
A28: 17 - State income tax | B28: 2288 | C28: 2288 | D28: OK | E28: Entered 2026-09-23 22:38:50 QA | H28: W2 | I28: FIELD
A30: W-2 #2 - 84-7654321 | Aurora School District - entered 2026-09-23 22:38:50 by QA - Complete - some fields not read back | H30: W2 | I30: INSTANCE | J30: Complete - some fields not read back
A31: Evidence: screenshot 223850_6789_W2_2.png (SHA-256 dac9b8759818a663...)
A32: Drake Screen Field | B32: Source Document (W-2) | C32: Entered in Drake | D32: Verified | E32: Last Action | F32: Reviewer | G32: Notes
A33: TS - Taxpayer / Spouse | B33: S | C33: S | D33: Not read back | E33: Entered 2026-09-23 22:38:50 QA | G33: Can't be read back; check the screenshot. | H33: W2 | I33: FIELD
A34: b - Employer identification number (EIN) | B34: 84-7654321 | C34: 847654321 | D34: OK | E34: Entered 2026-09-23 22:38:50 QA | H34: W2 | I34: FIELD
A35: c - Employer name | B35: Aurora School District | C35: Aurora School District | D35: OK | E35: Entered 2026-09-23 22:38:50 QA | H35: W2 | I35: FIELD
A36: c - Employer city | B36: Aurora | C36: Aurora | D36: OK | E36: Entered 2026-09-23 22:38:50 QA | H36: W2 | I36: FIELD
A37: c - Employer state | B37: CO | C37: CO | D37: OK | E37: Entered 2026-09-23 22:38:50 QA | H37: W2 | I37: FIELD
A38: c - Employer ZIP | B38: 80010 | C38: 80010 | D38: OK | E38: Entered 2026-09-23 22:38:50 QA | H38: W2 | I38: FIELD
A39: 1 - Wages, tips, other compensation | B39: 38500 | C39: 38500 | D39: OK | E39: Entered 2026-09-23 22:38:50 QA | H39: W2 | I39: FIELD
A40: 2 - Federal income tax withheld | B40: 2900 | C40: 2900 | D40: OK | E40: Entered 2026-09-23 22:38:50 QA | H40: W2 | I40: FIELD
A41: 3 - Social security wages | B41: 38500 | C41: 38500 | D41: OK | E41: Entered 2026-09-23 22:38:50 QA | H41: W2 | I41: FIELD
A42: 4 - Social security tax withheld | B42: 2387 | C42: 2387 | D42: OK | E42: Entered 2026-09-23 22:38:50 QA | H42: W2 | I42: FIELD
A43: 5 - Medicare wages and tips | B43: 38500 | C43: 38500 | D43: OK | E43: Entered 2026-09-23 22:38:50 QA | H43: W2 | I43: FIELD
A44: 6 - Medicare tax withheld | B44: 558.25 | C44: 558.25 | D44: OK | E44: Entered 2026-09-23 22:38:50 QA | H44: W2 | I44: FIELD
...

Sheet 4321 Lee Chen
A1: Lee Chen (***-**-4321) - Drake Entry Tracker
A2: Source Document = input workbook value. Entered in Drake = value read back from the Drake screen (typed value where the field can't be read back). Reviewer: initial each line or each document.
A4: FORM W-2 - WAGE AND TAX STATEMENT
A6: W-2 #1 - 20-1112299 | Peak Logistics Inc - entered 2026-09-23 22:38:50 by QA - Complete - some fields not read back | H6: W2 | I6: INSTANCE | J6: Complete - some fields not read back
A7: Evidence: screenshot 223855_4321_W2_1.png (SHA-256 dac9b8759818a663...)
A8: Last verified/corrected: 2026-09-23 22:38:56 QA
A9: Drake Screen Field | B9: Source Document (W-2) | C9: Entered in Drake | D9: Verified | E9: Last Action | F9: Reviewer | G9: Notes
A10: TS - Taxpayer / Spouse | B10: T | C10: T | D10: Not read back | E10: Verified 2026-09-23 22:38:56 QA | G10: Can't be read back; check the screenshot. | H10: W2 | I10: FIELD
A11: b - Employer identification number (EIN) | B11: 20-1112299 | C11: 201112299 | D11: OK | E11: Verified 2026-09-23 22:38:56 QA | H11: W2 | I11: FIELD
A12: c - Employer name | B12: Peak Logistics Inc | C12: Peak Logistics Inc | D12: OK | E12: Verified 2026-09-23 22:38:56 QA | H12: W2 | I12: FIELD
A13: c - Employer city | B13: Denver | C13: Denver | D13: OK | E13: Verified 2026-09-23 22:38:56 QA | H13: W2 | I13: FIELD
A14: c - Employer state | B14: CO | C14: CO | D14: OK | E14: Verified 2026-09-23 22:38:56 QA | H14: W2 | I14: FIELD
A15: c - Employer ZIP | B15: 80216 | C15: 80216 | D15: OK | E15: Verified 2026-09-23 22:38:56 QA | H15: W2 | I15: FIELD
A16: 1 - Wages, tips, other compensation | B16: 61000 | C16: 61000 | D16: OK | E16: Verified 2026-09-23 22:38:56 QA | H16: W2 | I16: FIELD
A17: 2 - Federal income tax withheld | B17: 6100 | C17: 6100 | D17: OK | E17: Verified 2026-09-23 22:38:56 QA | H17: W2 | I17: FIELD
A18: 3 - Social security wages | B18: 61000 | C18: 61000 | D18: OK | E18: Verified 2026-09-23 22:38:56 QA | H18: W2 | I18: FIELD
A19: 4 - Social security tax withheld | B19: 3782 | C19: 3782 | D19: OK | E19: Verified 2026-09-23 22:38:56 QA | H19: W2 | I19: FIELD
A20: 5 - Medicare wages and tips | B20: 61000 | C20: 61000 | D20: OK | E20: Verified 2026-09-23 22:38:56 QA | H20: W2 | I20: FIELD
A21: 6 - Medicare tax withheld | B21: 884.50 | C21: 884.50 | D21: OK | E21: Verified 2026-09-23 22:38:56 QA | H21: W2 | I21: FIELD
A22: 15 - State | B22: CO | C22: CO | D22: OK | E22: Verified 2026-09-23 22:38:56 QA | H22: W2 | I22: FIELD
... A24: 17 - State income tax | B24: 2684 | C24: 2684 | D24: OK | E24: Verified 2026-09-23 22:38:56 QA | H24: W2 | I24: FIELD

Sheet 2222 Kim Patel
A1: Kim Patel (***-**-2222) - Drake Entry Tracker
A2: Source Document = input workbook value. Entered in Drake = value read back from the Drake screen (typed value where the field can't be read back). Reviewer: initial each line or each document.
A4: FORM W-2 - WAGE AND TAX STATEMENT
A6: W-2 #1 - 33-4445556 | Summit Dental PC - entered 2026-09-23 22:38:54 by QA - Complete - some fields not read back | H6: W2 | I6: INSTANCE | J6: Complete - some fields not read back
A7: Evidence: screenshot 223854_2222_W2_1.png (SHA-256 dac9b8759818a663...)
A8: Drake Screen Field | B8: Source Document (W-2) | C8: Entered in Drake | D8: Verified | E8: Last Action | F8: Reviewer | G8: Notes
A9: TS - Taxpayer / Spouse | B9: T | C9: T | D9: Not read back | E9: Entered 2026-09-23 22:38:54 QA | G9: Can't be read back; check the screenshot. | H9: W2 | I9: FIELD
A10: b - Employer identification number (EIN) | B10: 33-4445556 | C10: 334445556 | D10: OK | E10: Entered 2026-09-23 22:38:54 QA | H10: W2 | I10: FIELD
A11: c - Employer name | B11: Summit Dental PC | C11: Summit Dental PC | D11: OK | E11: Entered 2026-09-23 22:38:54 QA | G11: Drake had pre-filled 'SUMMIT DENTAL'; replaced with the source value. | H11: W2 | I11: FIELD
A12: c - Employer city | B12: Boulder | C12: Boulder | D12: OK | E12: Entered 2026-09-23 22:38:54 QA | H12: W2 | I12: FIELD
A13: c - Employer state | B13: CO | C13: CO | D13: OK | E13: Entered 2026-09-23 22:38:54 QA | H13: W2 | I13: FIELD
A14: c - Employer ZIP | B14: 80302 | C14: 80302 | D14: OK | E14: Entered 2026-09-23 22:38:54 QA | H14: W2 | I14: FIELD
A15: 1 - Wages, tips, other compensation | B15: 47000 | C15: 47000 | D15: OK | E15: Entered 2026-09-23 22:38:54 QA | H15: W2 | I15: FIELD
A16: 2 - Federal income tax withheld | B16: 3900 | C16: 3900 | D16: OK | E16: Entered 2026-09-23 22:38:54 QA | H16: W2 | I16: FIELD
A17: 3 - Social security wages | B17: 47000 | C17: 47000 | D17: OK | E17: Entered 2026-09-23 22:38:54 QA | H17: W2 | I17: FIELD
A18: 4 - Social security tax withheld | B18: 2914 | C18: 2914 | D18: OK | E18: Entered 2026-09-23 22:38:54 QA | H18: W2 | I18: FIELD
A19: 5 - Medicare wages and tips | B19: 47000 | C19: 47000 | D19: OK | E19: Entered 2026-09-23 22:38:54 QA | H19: W2 | I19: FIELD
A20: 6 - Medicare tax withheld | B20: 681.50 | C20: 681.50 | D20: OK | E20: Entered 2026-09-23 22:38:54 QA | H20: W2 | I20: FIELD
