Workbook

Sheet Summary
A1: Brokerage 1099 Summary - Sample Client
A2: Preparer workpaper for data entry - not tax advice. Recipient TIN and account numbers shown as last 4 only.
A4: Client | B4: Sample Client
A5: Tax year | B5: 2025
A6: Broker | B6: Example Brokerage
A7: Statement date | B7: 46067
A8: Status | B8: Original
A9: Recipient TIN | B9: ****6789
A10: Forms present | B10: 1099-B, 1099-DA, 1099-DIV, 1099-INT, 1099-OID, 1099-MISC
A11: Source file | B11: sample_consolidated_1099.pdf
A13: Payer name | B13: Payer EIN | D13: Account | F13: Forms covered
A14: Example Brokerage LLC | B14: 12-3456789 | D14: ****5678 | F14: 1099-B, 1099-DIV, 1099-INT, 1099-OID, 1099-MISC
A15: Example Digital Assets LLC | B15: 98-7654321 | D15: ****9999 | F15: 1099-DA
A17: Form 8949 one-line entry - basis REPORTED to IRS
A18: Term | B18: 8949 box | C18: (d) Proceeds | D18: (e) Cost basis | E18: (f) Code | F18: (g) Wash sale adj | G18: (h) Gain/(loss) | H18: Payer EIN | I18: Note
A19: Short-term | B19: A | C19: ='1099-B Lots'!I48 -> 31200 | D19: ='1099-B Lots'!J48 -> 32500 | E19: =IF(F19<>0,"W","") -> W | F19: ='1099-B Lots'!L48 -> 850 | G19: =C19-D19+F19 -> -450 | H19: 12-3456789
A20: Short-term - Ordinary | B20: A | C20: ='1099-B Lots'!I49 -> 10000 | D20: ='1099-B Lots'!J49 -> 9790 | E20: =IF(F20<>0,"W","") | F20: ='1099-B Lots'!L49 -> 0 | G20: =C20-D20+F20 -> 210 | H20: 12-3456789
A21: Long-term | B21: D | C21: ='1099-B Lots'!I50 -> 27400 | D21: ='1099-B Lots'!J50 -> 13550 | E21: =IF(F21<>0,"W","") | F21: ='1099-B Lots'!L50 -> 0 | G21: =C21-D21+F21 -> 13850 | H21: 12-3456789
A22: Digital asset short-term | B22: G | C22: ='Crypto 1099-DA'!I31 -> 5500 | D22: ='Crypto 1099-DA'!J31 -> 4100 | E22: =IF(F22<>0,"W","") | F22: ='Crypto 1099-DA'!L31 -> 0 | G22: =C22-D22+F22 -> 1400 | H22: 98-7654321
A23: Digital asset long-term | B23: J | C23: ='Crypto 1099-DA'!I32 -> 0 | D23: ='Crypto 1099-DA'!J32 -> 0 | E23: =IF(F23<>0,"W","") | F23: ='Crypto 1099-DA'!L32 -> 0 | G23: =C23-D23+F23 -> 0 | H23: 98-7654321 | I23: None reported
A25: Tie-out to amounts reported (per term)
A26: Short-term, basis reported to IRS (Box A)
A27: Proceeds - Cost = Gain/(loss) before wash | G27: =(C19-D19)+(C20-D20) -> -1090
A28: Add: wash sale loss disallowed (Wash Sales tab) | G28: ='Wash Sales'!H18 -> 850
A29: Equals: reportable gain/(loss) | G29: =G27+G28 -> -240
A30: Broker-reported gain/(loss) (1099-B summary p.3) | G30: -240
A31: Diff (must be 0) | G31: =ROUND(G29-N(G30),2) -> 0
A32: Wash sale detail by security | B32: CUSIP | F32: # lines | G32: Disallowed
A33: APPLE INC | B33: 037833100 | F33: ='Wash Sales'!D13 -> 1 | G33: ='Wash Sales'!H13 -> 500
A34: TESLA INC | B34: 88160R101 | F34: ='Wash Sales'!D14 -> 1 | G34: ='Wash Sales'!H14 -> 350
A35: Total | F35: =SUM(F33:F34) -> 2 | G35: =SUM(G33:G34) -> 850
A36: Broker wash total (1099-B summary) | G36: =N('1099-B Lots'!L32) -> 850
A37: Diff (must be 0) | G37: =ROUND(G35-G36,2) -> 0
A39: Long-term, basis reported to IRS (Box D)
A40: Proceeds - Cost = Gain/(loss) before wash | G40: =(C21-D21) -> 13850
A41: Add: wash sale loss disallowed (Wash Sales tab) | G41: ='Wash Sales'!H20 -> 0
A42: Equals: reportable gain/(loss) | G42: =G40+G41 -> 13850
A43: Broker-reported gain/(loss) (1099-B summary p.3) | G43: 13850
A44: Diff (must be 0) | G44: =ROUND(G42-N(G43),2) -> 0
A45: No wash sales reported in Box D.
...

Sheet 1099-B Lots
A1: 1099-B Lots - Sample Client - 2025 Example Brokerage
A2: Blue = keyed from the 1099 (page in Src page column). Black = formula. Calc gain = proceeds - cost + wash; Diff = calc - broker (must be 0).
A4: Box | B4: Term | C4: Ord | D4: Security | E4: CUSIP | F4: Qty | G4: Date acquired | H4: Date sold | I4: Proceeds (d) | J4: Cost basis (e) | K4: Market discount | L4: Wash sale (g) | M4: Broker gain/(loss) | N4: Calc gain/(loss) | O4: Diff | P4: Account | Q4: Notes | R4: Src page
A5: A | B5: ST | C5: N | D5: APPLE INC | E5: 037833100 | F5: 50 | G5: 45667 | H5: 45719 | I5: 11250 | J5: 12000 | K5: 0 | L5: 0 | M5: -750 | N5: =I5-J5+L5 -> -750 | O5: =ROUND(N5-M5,2) -> 0 | P5: 5678 | R5: 7
A6: A | B6: ST | C6: N | D6: APPLE INC | E6: 037833100 | F6: 20 | G6: 45726 | H6: 45762 | I6: 3900 | J6: 4400 | K6: 0 | L6: 500 | M6: 0 | N6: =I6-J6+L6 -> 0 | O6: =ROUND(N6-M6,2) -> 0 | P6: 5678 | R6: 7
A7: A | B7: ST | C7: N | D7: APPLE INC | E7: 037833100 | F7: 30 | G7: 45767 | H7: 45989 | I7: 7050 | J7: 6650 | K7: 0 | L7: 0 | M7: 400 | N7: =I7-J7+L7 -> 400 | O7: =ROUND(N7-M7,2) -> 0 | P7: 5678 | R7: 7
A8: A | B8: ST | C8: N | D8: SPDR S&P 500 ETF TRUST | E8: 78462F103 | F8: 5 | G8: 45778 | H8: 45828 | I8: 2900 | J8: 2700 | K8: 0 | L8: 0 | M8: 200 | N8: =I8-J8+L8 -> 200 | O8: =ROUND(N8-M8,2) -> 0 | P8: 5678 | R8: 8
A9: A | B9: ST | C9: N | D9: TESLA INC | E9: 88160R101 | F9: 10 | G9: 45691 | H9: 45708 | I9: 3100 | J9: 3300 | K9: 0 | L9: 350 | M9: 150 | N9: =I9-J9+L9 -> 150 | O9: =ROUND(N9-M9,2) -> 0 | P9: 5678 | Q9: Aggregated lots | R9: 8
A10: A | B10: ST | C10: N | D10: TESLA INC | E10: 88160R101 | F10: 10 | G10: 45713 | H10: 45810 | I10: 3000 | J10: 3450 | K10: 0 | L10: 0 | M10: -450 | N10: =I10-J10+L10 -> -450 | O10: =ROUND(N10-M10,2) -> 0 | P10: 5678 | R10: 8
A11: A | B11: ST | C11: Y | D11: US TREASURY BILL 0% 08/14/25 | E11: 912797KX4 | F11: 10000 | G11: 45701 | H11: 45883 | I11: 10000 | J11: 9790 | K11: 0 | L11: 0 | M11: 210 | N11: =I11-J11+L11 -> 210 | O11: =ROUND(N11-M11,2) -> 0 | P11: 5678 | Q11: Ordinary: discount | R11: 9
A12: B | B12: ST | C12: N | D12: ABC CORP CVR | E12: 000360206 | F12: 100 | G12: 45659 | H12: 45931 | I12: 40 | J12: 0 | K12: 0 | L12: 0 | M12: 40 | N12: =I12-J12+L12 -> 40 | O12: =ROUND(N12-M12,2) -> 0 | P12: 5678 | Q12: CVR | R12: 11
A13: B | B13: ST | C13: N | D13: GENERAL ELECTRIC CO | E13: 369604301 | F13: 25 | G13: VARIOUS | H13: 45789 | I13: 4125 | J13: N/A | K13: 0 | L13: 0 | M13: N/A | P13: 5678 | Q13: Noncovered | R13: 11
A14: D | B14: LT | C14: N | D14: MICROSOFT CORP | E14: 594918104 | F14: 40 | G14: 43619 | H14: 45852 | I14: 20100 | J14: 5200 | K14: 0 | L14: 0 | M14: 14900 | N14: =I14-J14+L14 -> 14900 | O14: =ROUND(N14-M14,2) -> 0 | P14: 5678 | R14: 10
A15: D | B15: LT | C15: N | D15: VANGUARD TOTAL BOND MARKET ETF | E15: 921937835 | F15: 100 | G15: 43845 | H15: 45930 | I15: 7300 | J15: 8350 | K15: 0 | L15: 0 | M15: -1050 | N15: =I15-J15+L15 -> -1050 | O15: =ROUND(N15-M15,2) -> 0 | P15: 5678 | R15: 10
A16: E | B16: LT | C16: N | D16: COCA COLA CO | E16: 191216100 | F16: 60 | G16: 39539 | H16: 45887 | I16: 4200 | J16: 1500 | K16: 0 | L16: 0 | M16: 2700 | N16: =I16-J16+L16 -> 2700 | O16: =ROUND(N16-M16,2) -> 0 | P16: 5678 | Q16: Original basis: 1,500.00 | R16: 12
A17: X | B17: UNKNOWN | C17: N | D17: OLD MUTUAL FUND | E17: 001234AB9 | F17: 75 | G17: N/A | H17: 45996 | I17: 2600 | J17: N/A | K17: 0 | L17: 0 | M17: N/A | P17: 5678 | Q17: Term unknown | R17: 13
D19: Per-lot check: sum of |Diff| (must be 0) | O19: =ROUND(SUMPRODUCT(ABS($O$5:$O$17)),2) -> 0
A21: Totals by 8949 box (sum of lots)
A22: Box | D22: Description | F22: # lots | I22: Proceeds (d) | J22: Cost basis (e) | K22: Market discount | L22: Wash sale (g) | M22: Broker gain/(loss) | N22: Calc gain/(loss)
A23: A | D23: Short-term, basis reported to IRS | F23: =COUNTIF($A$5:$A$17,$A23) -> 7 | I23: =SUMIFS($I$5:$I$17,$A$5:$A$17,$A23) -> 41200 | J23: =SUMIFS($J$5:$J$17,$A$5:$A$17,$A23) -> 42290 | K23: =SUMIFS($K$5:$K$17,$A$5:$A$17,$A23) -> 0 | L23: =SUMIFS($L$5:$L$17,$A$5:$A$17,$A23) -> 850 | M23: =SUMIFS($M$5:$M$17,$A$5:$A$17,$A23) -> -240 | N23: =SUMIFS($N$5:$N$17,$A$5:$A$17,$A23) -> -240
A24: B | D24: Short-term, basis NOT reported | F24: =COUNTIF($A$5:$A$17,$A24) -> 2 | I24: =SUMIFS($I$5:$I$17,$A$5:$A$17,$A24) -> 4165 | J24: =SUMIFS($J$5:$J$17,$A$5:$A$17,$A24) -> 0 | K24: =SUMIFS($K$5:$K$17,$A$5:$A$17,$A24) -> 0 | L24: =SUMIFS($L$5:$L$17,$A$5:$A$17,$A24) -> 0 | M24: =SUMIFS($M$5:$M$17,$A$5:$A$17,$A24) -> 40 | N24: =SUMIFS($N$5:$N$17,$A$5:$A$17,$A24) -> 40
A25: D | D25: Long-term, basis reported to IRS | F25: =COUNTIF($A$5:$A$17,$A25) -> 2 | I25: =SUMIFS($I$5:$I$17,$A$5:$A$17,$A25) -> 27400 | J25: =SUMIFS($J$5:$J$17,$A$5:$A$17,$A25) -> 13550 | K25: =SUMIFS($K$5:$K$17,$A$5:$A$17,$A25) -> 0 | L25: =SUMIFS($L$5:$L$17,$A$5:$A$17,$A25) -> 0 | M25: =SUMIFS($M$5:$M$17,$A$5:$A$17,$A25) -> 13850 | N25: =SUMIFS($N$5:$N$17,$A$5:$A$17,$A25) -> 13850
A26: E | D26: Long-term, basis NOT reported | F26: =COUNTIF($A$5:$A$17,$A26) -> 1 | I26: =SUMIFS($I$5:$I$17,$A$5:$A$17,$A26) -> 4200 | J26: =SUMIFS($J$5:$J$17,$A$5:$A$17,$A26) -> 1500 | K26: =SUMIFS($K$5:$K$17,$A$5:$A$17,$A26) -> 0 | L26: =SUMIFS($L$5:$L$17,$A$5:$A$17,$A26) -> 0 | M26: =SUMIFS($M$5:$M$17,$A$5:$A$17,$A26) -> 2700 | N26: =SUMIFS($N$5:$N$17,$A$5:$A$17,$A26) -> 2700
A27: X | D27: Unknown term (term and basis from client) | F27: =COUNTIF($A$5:$A$17,$A27) -> 1 | I27: =SUMIFS($I$5:$I$17,$A$5:$A$17,$A27) -> 2600 | J27: =SUMIFS($J$5:$J$17,$A$5:$A$17,$A27) -> 0 | K27: =SUMIFS($K$5:$K$17,$A$5:$A$17,$A27) -> 0 | L27: =SUMIFS($L$5:$L$17,$A$5:$A$17,$A27) -> 0 | M27: =SUMIFS($M$5:$M$17,$A$5:$A$17,$A27) -> 0 | N27: =SUMIFS($N$5:$N$17,$A$5:$A$17,$A27) -> 0
A28: Total | F28: =SUM(F23:F27) -> 13 | I28: =SUM(I23:I27) -> 79565 | J28: =SUM(J23:J27) -> 57340 | K28: =SUM(K23:K27) -> 0 | L28: =SUM(L23:L27) -> 850 | M28: =SUM(M23:M27) -> 16350 | N28: =SUM(N23:N27) -> 16350
A30: Broker 1099-B summary totals (keyed from the summary page)
A31: Box | D31: Source | I31: Proceeds (d) | J31: Cost basis (e) | K31: Market discount | L31: Wash sale (g) | M31: Broker gain/(loss)
A32: A | D32: 1099-B summary p.3 | I32: 41200 | J32: 42290 | K32: 0 | L32: 850 | M32: -240
A33: B | D33: 1099-B summary p.3 | I33: 4165 | J33: N/A | K33: 0 | L33: 0 | M33: 40
A34: D | D34: 1099-B summary p.3 | I34: 27400 | J34: 13550 | K34: 0 | L34: 0 | M34: 13850
A35: E | D35: 1099-B summary p.3 | I35: 4200 | J35: 1500 | K35: 0 | L35: 0 | M35: 2700
A36: X | D36: 1099-B summary p.3 | I36: 2600 | J36: N/A | K36: 0 | L36: 0 | M36: N/A
A38: Diff: sum of lots - broker summary (must be 0)
A39: Box | I39: Proceeds | J39: Cost | K39: Market discount | L39: Wash sale | M39: Gain/(loss)
A40: A | I40: =ROUND(I23-N(I32),2) -> 0 | J40: =ROUND(J23-N(J32),2) -> 0 | K40: =ROUND(K23-N(K32),2) -> 0 | L40: =ROUND(L23-N(L32),2) -> 0 | M40: =ROUND(M23-N(M32),2) -> 0
A41: B | I41: =ROUND(I24-N(I33),2) -> 0 | J41: =ROUND(J24-N(J33),2) -> 0 | K41: =ROUND(K24-N(K33),2) -> 0 | L41: =ROUND(L24-N(L33),2) -> 0 | M41: =ROUND(M24-N(M33),2) -> 0
A42: D | I42: =ROUND(I25-N(I34),2) -> 0 | J42: =ROUND(J25-N(J34),2) -> 0 | K42: =ROUND(K25-N(K34),2) -> 0 | L42: =ROUND(L25-N(L34),2) -> 0 | M42: =ROUND(M25-N(M34),2) -> 0
A43: E | I43: =ROUND(I26-N(I35),2) -> 0 | J43: =ROUND(J26-N(J35),2) -> 0 | K43: =ROUND(K26-N(K35),2) -> 0 | L43: =ROUND(L26-N(L35),2) -> 0 | M43: =ROUND(M26-N(M35),2) -> 0
A44: X | I44: =ROUND(I27-N(I36),2) -> 0 | J44: =ROUND(J27-N(J36),2) -> 0 | K44: =ROUND(K27-N(K36),2) -> 0 | L44: =ROUND(L27-N(L36),2) -> 0 | M44: =ROUND(M27-N(M36),2) -> 0
A46: Form 8949 entry lines - basis reported (linked to Summary)
...

Sheet By Security
A1: By Security - Sample Client - 2025
A2: All figures are SUMPRODUCTs of the 1099-B Lots tab, matched on CUSIP (or description when no CUSIP).
A4: Security | B4: CUSIP | C4: # lots | D4: Proceeds | E4: Basis | F4: Wash sale | G4: Net (broker gain/(loss)) | H4: Net (calc)
A5: ABC CORP CVR | B5: 000360206 | C5: =SUMPRODUCT(--('1099-B Lots'!$E$5:$E$17=$B5)) -> 1 | D5: =SUMPRODUCT(--('1099-B Lots'!$E$5:$E$17=$B5),'1099-B Lots'!$I$5:$I$17) -> 40 | E5: =SUMPRODUCT(--('1099-B Lots'!$E$5:$E$17=$B5),'1099-B Lots'!$J$5:$J$17) -> 0 | F5: =SUMPRODUCT(--('1099-B Lots'!$E$5:$E$17=$B5),'1099-B Lots'!$L$5:$L$17) -> 0 | G5: =SUMPRODUCT(--('1099-B Lots'!$E$5:$E$17=$B5),'1099-B Lots'!$M$5:$M$17) -> 40 | H5: =SUMPRODUCT(--('1099-B Lots'!$E$5:$E$17=$B5),'1099-B Lots'!$N$5:$N$17) -> 40
A6: APPLE INC | B6: 037833100 | C6: =SUMPRODUCT(--('1099-B Lots'!$E$5:$E$17=$B6)) -> 3 | D6: =SUMPRODUCT(--('1099-B Lots'!$E$5:$E$17=$B6),'1099-B Lots'!$I$5:$I$17) -> 22200 | E6: =SUMPRODUCT(--('1099-B Lots'!$E$5:$E$17=$B6),'1099-B Lots'!$J$5:$J$17) -> 23050 | F6: =SUMPRODUCT(--('1099-B Lots'!$E$5:$E$17=$B6),'1099-B Lots'!$L$5:$L$17) -> 500 | G6: =SUMPRODUCT(--('1099-B Lots'!$E$5:$E$17=$B6),'1099-B Lots'!$M$5:$M$17) -> -350 | H6: =SUMPRODUCT(--('1099-B Lots'!$E$5:$E$17=$B6),'1099-B Lots'!$N$5:$N$17) -> -350
A7: COCA COLA CO | B7: 191216100 | C7: =SUMPRODUCT(--('1099-B Lots'!$E$5:$E$17=$B7)) -> 1 | D7: =SUMPRODUCT(--('1099-B Lots'!$E$5:$E$17=$B7),'1099-B Lots'!$I$5:$I$17) -> 4200 | E7: =SUMPRODUCT(--('1099-B Lots'!$E$5:$E$17=$B7),'1099-B Lots'!$J$5:$J$17) -> 1500 | F7: =SUMPRODUCT(--('1099-B Lots'!$E$5:$E$17=$B7),'1099-B Lots'!$L$5:$L$17) -> 0 | G7: =SUMPRODUCT(--('1099-B Lots'!$E$5:$E$17=$B7),'1099-B Lots'!$M$5:$M$17) -> 2700 | H7: =SUMPRODUCT(--('1099-B Lots'!$E$5:$E$17=$B7),'1099-B Lots'!$N$5:$N$17) -> 2700
A8: GENERAL ELECTRIC CO | B8: 369604301 | C8: =SUMPRODUCT(--('1099-B Lots'!$E$5:$E$17=$B8)) -> 1 | D8: =SUMPRODUCT(--('1099-B Lots'!$E$5:$E$17=$B8),'1099-B Lots'!$I$5:$I$17) -> 4125 | E8: =SUMPRODUCT(--('1099-B Lots'!$E$5:$E$17=$B8),'1099-B Lots'!$J$5:$J$17) -> 0 | F8: =SUMPRODUCT(--('1099-B Lots'!$E$5:$E$17=$B8),'1099-B Lots'!$L$5:$L$17) -> 0 | G8: =SUMPRODUCT(--('1099-B Lots'!$E$5:$E$17=$B8),'1099-B Lots'!$M$5:$M$17) -> 0 | H8: =SUMPRODUCT(--('1099-B Lots'!$E$5:$E$17=$B8),'1099-B Lots'!$N$5:$N$17) -> 0
A9: MICROSOFT CORP | B9: 594918104 | C9: =SUMPRODUCT(--('1099-B Lots'!$E$5:$E$17=$B9)) -> 1 | D9: =SUMPRODUCT(--('1099-B Lots'!$E$5:$E$17=$B9),'1099-B Lots'!$I$5:$I$17) -> 20100 | E9: =SUMPRODUCT(--('1099-B Lots'!$E$5:$E$17=$B9),'1099-B Lots'!$J$5:$J$17) -> 5200 | F9: =SUMPRODUCT(--('1099-B Lots'!$E$5:$E$17=$B9),'1099-B Lots'!$L$5:$L$17) -> 0 | G9: =SUMPRODUCT(--('1099-B Lots'!$E$5:$E$17=$B9),'1099-B Lots'!$M$5:$M$17) -> 14900 | H9: =SUMPRODUCT(--('1099-B Lots'!$E$5:$E$17=$B9),'1099-B Lots'!$N$5:$N$17) -> 14900
A10: OLD MUTUAL FUND | B10: 001234AB9 | C10: =SUMPRODUCT(--('1099-B Lots'!$E$5:$E$17=$B10)) -> 1 | D10: =SUMPRODUCT(--('1099-B Lots'!$E$5:$E$17=$B10),'1099-B Lots'!$I$5:$I$17) -> 2600 | E10: =SUMPRODUCT(--('1099-B Lots'!$E$5:$E$17=$B10),'1099-B Lots'!$J$5:$J$17) -> 0 | F10: =SUMPRODUCT(--('1099-B Lots'!$E$5:$E$17=$B10),'1099-B Lots'!$L$5:$L$17) -> 0 | G10: =SUMPRODUCT(--('1099-B Lots'!$E$5:$E$17=$B10),'1099-B Lots'!$M$5:$M$17) -> 0 | H10: =SUMPRODUCT(--('1099-B Lots'!$E$5:$E$17=$B10),'1099-B Lots'!$N$5:$N$17) -> 0
A11: SPDR S&P 500 ETF TRUST | B11: 78462F103 | C11: =SUMPRODUCT(--('1099-B Lots'!$E$5:$E$17=$B11)) -> 1 | D11: =SUMPRODUCT(--('1099-B Lots'!$E$5:$E$17=$B11),'1099-B Lots'!$I$5:$I$17) -> 2900 | E11: =SUMPRODUCT(--('1099-B Lots'!$E$5:$E$17=$B11),'1099-B Lots'!$J$5:$J$17) -> 2700 | F11: =SUMPRODUCT(--('1099-B Lots'!$E$5:$E$17=$B11),'1099-B Lots'!$L$5:$L$17) -> 0 | G11: =SUMPRODUCT(--('1099-B Lots'!$E$5:$E$17=$B11),'1099-B Lots'!$M$5:$M$17) -> 200 | H11: =SUMPRODUCT(--('1099-B Lots'!$E$5:$E$17=$B11),'1099-B Lots'!$N$5:$N$17) -> 200
A12: TESLA INC | B12: 88160R101 | C12: =SUMPRODUCT(--('1099-B Lots'!$E$5:$E$17=$B12)) -> 2 | D12: =SUMPRODUCT(--('1099-B Lots'!$E$5:$E$17=$B12),'1099-B Lots'!$I$5:$I$17) -> 6100 | E12: =SUMPRODUCT(--('1099-B Lots'!$E$5:$E$17=$B12),'1099-B Lots'!$J$5:$J$17) -> 6750 | F12: =SUMPRODUCT(--('1099-B Lots'!$E$5:$E$17=$B12),'1099-B Lots'!$L$5:$L$17) -> 350 | G12: =SUMPRODUCT(--('1099-B Lots'!$E$5:$E$17=$B12),'1099-B Lots'!$M$5:$M$17) -> -300 | H12: =SUMPRODUCT(--('1099-B Lots'!$E$5:$E$17=$B12),'1099-B Lots'!$N$5:$N$17) -> -300
A13: US TREASURY BILL 0% 08/14/25 | B13: 912797KX4 | C13: =SUMPRODUCT(--('1099-B Lots'!$E$5:$E$17=$B13)) -> 1 | D13: =SUMPRODUCT(--('1099-B Lots'!$E$5:$E$17=$B13),'1099-B Lots'!$I$5:$I$17) -> 10000 | E13: =SUMPRODUCT(--('1099-B Lots'!$E$5:$E$17=$B13),'1099-B Lots'!$J$5:$J$17) -> 9790 | F13: =SUMPRODUCT(--('1099-B Lots'!$E$5:$E$17=$B13),'1099-B Lots'!$L$5:$L$17) -> 0 | G13: =SUMPRODUCT(--('1099-B Lots'!$E$5:$E$17=$B13),'1099-B Lots'!$M$5:$M$17) -> 210 | H13: =SUMPRODUCT(--('1099-B Lots'!$E$5:$E$17=$B13),'1099-B Lots'!$N$5:$N$17) -> 210
A14: VANGUARD TOTAL BOND MARKET ETF | B14: 921937835 | C14: =SUMPRODUCT(--('1099-B Lots'!$E$5:$E$17=$B14)) -> 1 | D14: =SUMPRODUCT(--('1099-B Lots'!$E$5:$E$17=$B14),'1099-B Lots'!$I$5:$I$17) -> 7300 | E14: =SUMPRODUCT(--('1099-B Lots'!$E$5:$E$17=$B14),'1099-B Lots'!$J$5:$J$17) -> 8350 | F14: =SUMPRODUCT(--('1099-B Lots'!$E$5:$E$17=$B14),'1099-B Lots'!$L$5:$L$17) -> 0 | G14: =SUMPRODUCT(--('1099-B Lots'!$E$5:$E$17=$B14),'1099-B Lots'!$M$5:$M$17) -> -1050 | H14: =SUMPRODUCT(--('1099-B Lots'!$E$5:$E$17=$B14),'1099-B Lots'!$N$5:$N$17) -> -1050
A15: Total | C15: =SUM(C5:C14) -> 13 | D15: =SUM(D5:D14) -> 79565 | E15: =SUM(E5:E14) -> 57340 | F15: =SUM(F5:F14) -> 850 | G15: =SUM(G5:G14) -> 16350 | H15: =SUM(H5:H14) -> 16350
A16: 1099-B Lots total (link) | C16: ='1099-B Lots'!F28 -> 13 | D16: ='1099-B Lots'!I28 -> 79565 | E16: ='1099-B Lots'!J28 -> 57340 | F16: ='1099-B Lots'!L28 -> 850 | G16: ='1099-B Lots'!M28 -> 16350 | H16: ='1099-B Lots'!N28 -> 16350
A17: Diff (must be 0) | C17: =ROUND(C15-C16,2) -> 0 | D17: =ROUND(D15-D16,2) -> 0 | E17: =ROUND(E15-E16,2) -> 0 | F17: =ROUND(F15-F16,2) -> 0 | G17: =ROUND(G15-G16,2) -> 0

Sheet Wash Sales
A1: Wash Sales - Sample Client - 2025
A2: Every lot with a non-zero 1099-B box 1g (keyed off the amount, not the W code). Green = linked to the lot tab.
A4: Box | B4: Security | C4: CUSIP | D4: Date acquired | E4: Date sold | F4: Proceeds | G4: Basis | H4: Disallowed (g) | I4: Broker gain/(loss) | J4: Calc gain/(loss) | K4: Diff | L4: Notes
A5: =T('1099-B Lots'!A6) -> A | B5: =T('1099-B Lots'!D6) -> APPLE INC | C5: =T('1099-B Lots'!E6) -> 037833100 | D5: ='1099-B Lots'!G6 -> 45726 | E5: ='1099-B Lots'!H6 -> 45762 | F5: ='1099-B Lots'!I6 -> 3900 | G5: ='1099-B Lots'!J6 -> 4400 | H5: ='1099-B Lots'!L6 -> 500 | I5: ='1099-B Lots'!M6 -> 0 | J5: =IF(ISNUMBER(G5),F5-G5+H5,"") -> 0 | K5: =IF(AND(ISNUMBER(J5),ISNUMBER(I5)),ROUND(J5-I5,2),0) -> 0 | L5: Later sales of this security through 11/28/2025 with no wash on the final sale: position likely closed and deferred loss realized this year (confirm no shares at 12/31).
A6: =T('1099-B Lots'!A9) -> A | B6: =T('1099-B Lots'!D9) -> TESLA INC | C6: =T('1099-B Lots'!E9) -> 88160R101 | D6: ='1099-B Lots'!G9 -> 45691 | E6: ='1099-B Lots'!H9 -> 45708 | F6: ='1099-B Lots'!I9 -> 3100 | G6: ='1099-B Lots'!J9 -> 3300 | H6: ='1099-B Lots'!L9 -> 350 | I6: ='1099-B Lots'!M9 -> 150 | J6: =IF(ISNUMBER(G6),F6-G6+H6,"") -> 150 | K6: =IF(AND(ISNUMBER(J6),ISNUMBER(I6)),ROUND(J6-I6,2),0) -> 0 | L6: Disallowed amount exceeds this line's pre-adjustment loss: broker aggregated several lots; reported as the broker computed. Later sales of this security through 06/02/2025 with no wash on the final sale: position likely closed and deferred loss realized this year (confirm no shares at 12/31).
B7: Total | F7: =SUM(F5:F6) -> 7000 | G7: =SUM(G5:G6) -> 7700 | H7: =SUM(H5:H6) -> 850 | I7: =SUM(I5:I6) -> 150 | K7: =ROUND(SUMPRODUCT(ABS(K5:K6)),2) -> 0
B8: Wash total on lot tab(s) (link) | H8: ='1099-B Lots'!L28+'Crypto 1099-DA'!L15 -> 850
B9: Diff: Wash Sales tab - lot tab(s) (must be 0) | H9: =ROUND(H7-H8,2) -> 0
A11: Wash sales by security
A12: Box | B12: Security | C12: CUSIP | D12: # lines | H12: Disallowed
A13: A | B13: APPLE INC | C13: 037833100 | D13: =SUMPRODUCT(--($A$5:$A$6=$A13),--($C$5:$C$6=$C13)) -> 1 | H13: =SUMPRODUCT(--($A$5:$A$6=$A13),--($C$5:$C$6=$C13),$H$5:$H$6) -> 500
A14: A | B14: TESLA INC | C14: 88160R101 | D14: =SUMPRODUCT(--($A$5:$A$6=$A14),--($C$5:$C$6=$C14)) -> 1 | H14: =SUMPRODUCT(--($A$5:$A$6=$A14),--($C$5:$C$6=$C14),$H$5:$H$6) -> 350
A16: Wash sale totals by box: detail vs broker (must be 0)
A17: Box | B17: Description | D17: # lines | F17: Lot tab wash (link) | G17: Broker wash total (link) | H17: Wash Sales detail | I17: Diff vs broker | J17: Diff vs lot tab
A18: A | B18: Short-term, basis reported to IRS | D18: =COUNTIF($A$5:$A$6,$A18) -> 2 | F18: ='1099-B Lots'!L23 -> 850 | G18: =N('1099-B Lots'!L32) -> 850 | H18: =SUMIFS($H$5:$H$6,$A$5:$A$6,$A18) -> 850 | I18: =ROUND(H18-G18,2) -> 0 | J18: =ROUND(H18-F18,2) -> 0
A19: B | B19: Short-term, basis NOT reported | D19: =COUNTIF($A$5:$A$6,$A19) -> 0 | F19: ='1099-B Lots'!L24 -> 0 | G19: =N('1099-B Lots'!L33) -> 0 | H19: =SUMIFS($H$5:$H$6,$A$5:$A$6,$A19) -> 0 | I19: =ROUND(H19-G19,2) -> 0 | J19: =ROUND(H19-F19,2) -> 0
A20: D | B20: Long-term, basis reported to IRS | D20: =COUNTIF($A$5:$A$6,$A20) -> 0 | F20: ='1099-B Lots'!L25 -> 0 | G20: =N('1099-B Lots'!L34) -> 0 | H20: =SUMIFS($H$5:$H$6,$A$5:$A$6,$A20) -> 0 | I20: =ROUND(H20-G20,2) -> 0 | J20: =ROUND(H20-F20,2) -> 0
A21: E | B21: Long-term, basis NOT reported | D21: =COUNTIF($A$5:$A$6,$A21) -> 0 | F21: ='1099-B Lots'!L26 -> 0 | G21: =N('1099-B Lots'!L35) -> 0 | H21: =SUMIFS($H$5:$H$6,$A$5:$A$6,$A21) -> 0 | I21: =ROUND(H21-G21,2) -> 0 | J21: =ROUND(H21-F21,2) -> 0
A22: X | B22: Unknown term (term and basis from client) | D22: =COUNTIF($A$5:$A$6,$A22) -> 0 | F22: ='1099-B Lots'!L27 -> 0 | G22: =N('1099-B Lots'!L36) -> 0 | H22: =SUMIFS($H$5:$H$6,$A$5:$A$6,$A22) -> 0 | I22: =ROUND(H22-G22,2) -> 0 | J22: =ROUND(H22-F22,2) -> 0
A23: G | B23: Digital asset short-term, basis reported | D23: =COUNTIF($A$5:$A$6,$A23) -> 0 | F23: ='Crypto 1099-DA'!L12 -> 0 | G23: =N('Crypto 1099-DA'!L19) -> 0 | H23: =SUMIFS($H$5:$H$6,$A$5:$A$6,$A23) -> 0 | I23: =ROUND(H23-G23,2) -> 0 | J23: =ROUND(H23-F23,2) -> 0
A24: H | B24: Digital asset short-term, basis NOT reported | D24: =COUNTIF($A$5:$A$6,$A24) -> 0 | F24: ='Crypto 1099-DA'!L13 -> 0 | G24: =N('Crypto 1099-DA'!L20) -> 0 | H24: =SUMIFS($H$5:$H$6,$A$5:$A$6,$A24) -> 0 | I24: =ROUND(H24-G24,2) -> 0 | J24: =ROUND(H24-F24,2) -> 0
A25: J | B25: Digital asset long-term, basis reported | D25: =COUNTIF($A$5:$A$6,$A25) -> 0 | F25: ='Crypto 1099-DA'!L14 -> 0 | G25: =N('Crypto 1099-DA'!L21) -> 0 | H25: =SUMIFS($H$5:$H$6,$A$5:$A$6,$A25) -> 0 | I25: =ROUND(H25-G25,2) -> 0 | J25: =ROUND(H25-F25,2) -> 0
A27: Notes
A28: - | B28: Reported-basis boxes (A/D/G/J) are entered as one summary line per term with code W and the disallowed amount in column (g). Not-reported boxes are entered lot by lot.
A29: - | B29: The broker tracks only same-account, identical-CUSIP wash sales. Ask about IRAs (loss permanently disallowed), spouse's accounts, other brokers and options.
A30: - | B30: Lines where the disallowed amount exceeds the line's own loss reflect broker aggregation of several lots; they are reported as the broker computed.
A31: - | B31: Digital assets that are not securities are not subject to the wash sale rule (confirm no law change for the year). Spot crypto ETFs/trusts are securities.

Sheet Noncovered Lots
A1: Noncovered / Unknown-Term Lots - ENTER EACH LOT INDIVIDUALLY - Sample Client 2025
A2: Green = linked to the lot tab. YELLOW = client must supply (example: date acquired 03/15/2019, term LT, basis 1,250.00). Basis to use = client basis if entered, else the 1099 basis.
A4: Box | B4: Term | C4: Security | D4: CUSIP | E4: Qty | F4: Date acquired (1099) | G4: Date sold | H4: Proceeds | I4: Cost (1099) | J4: Wash sale | K4: Broker gain/(loss) | L4: CLIENT date acquired | M4: CLIENT term (ST/LT) | N4: CLIENT basis | O4: Basis to use | P4: Calc gain/(loss) | Q4: What's missing | R4: Src page
A5: =T('1099-B Lots'!A13) -> B | B5: =T('1099-B Lots'!B13) -> ST | C5: =T('1099-B Lots'!D13) -> GENERAL ELECTRIC CO | D5: =T('1099-B Lots'!E13) -> 369604301 | E5: ='1099-B Lots'!F13 -> 25 | F5: ='1099-B Lots'!G13 -> VARIOUS | G5: ='1099-B Lots'!H13 -> 45789 | H5: ='1099-B Lots'!I13 -> 4125 | I5: ='1099-B Lots'!J13 -> N/A | J5: ='1099-B Lots'!L13 -> 0 | K5: ='1099-B Lots'!M13 -> N/A | O5: =IF(ISNUMBER(N5),N5,IF(ISNUMBER(I5),I5,"")) | P5: =IF(ISNUMBER(O5),H5-O5+J5,"") | Q5: basis, date acquired | R5: ='1099-B Lots'!R13 -> 11
A6: =T('1099-B Lots'!A12) -> B | B6: =T('1099-B Lots'!B12) -> ST | C6: =T('1099-B Lots'!D12) -> ABC CORP CVR | D6: =T('1099-B Lots'!E12) -> 000360206 | E6: ='1099-B Lots'!F12 -> 100 | F6: ='1099-B Lots'!G12 -> 45659 | G6: ='1099-B Lots'!H12 -> 45931 | H6: ='1099-B Lots'!I12 -> 40 | I6: ='1099-B Lots'!J12 -> 0 | J6: ='1099-B Lots'!L12 -> 0 | K6: ='1099-B Lots'!M12 -> 40 | O6: =IF(ISNUMBER(N6),N6,IF(ISNUMBER(I6),I6,"")) -> 0 | P6: =IF(ISNUMBER(O6),H6-O6+J6,"") -> 40 | Q6: verify basis with client | R6: ='1099-B Lots'!R12 -> 11
A7: =T('1099-B Lots'!A16) -> E | B7: =T('1099-B Lots'!B16) -> LT | C7: =T('1099-B Lots'!D16) -> COCA COLA CO | D7: =T('1099-B Lots'!E16) -> 191216100 | E7: ='1099-B Lots'!F16 -> 60 | F7: ='1099-B Lots'!G16 -> 39539 | G7: ='1099-B Lots'!H16 -> 45887 | H7: ='1099-B Lots'!I16 -> 4200 | I7: ='1099-B Lots'!J16 -> 1500 | J7: ='1099-B Lots'!L16 -> 0 | K7: ='1099-B Lots'!M16 -> 2700 | O7: =IF(ISNUMBER(N7),N7,IF(ISNUMBER(I7),I7,"")) -> 1500 | P7: =IF(ISNUMBER(O7),H7-O7+J7,"") -> 2700 | Q7: verify basis with client | R7: ='1099-B Lots'!R16 -> 12
A8: =T('1099-B Lots'!A17) -> X | B8: =T('1099-B Lots'!B17) -> UNKNOWN | C8: =T('1099-B Lots'!D17) -> OLD MUTUAL FUND | D8: =T('1099-B Lots'!E17) -> 001234AB9 | E8: ='1099-B Lots'!F17 -> 75 | F8: ='1099-B Lots'!G17 -> N/A | G8: ='1099-B Lots'!H17 -> 45996 | H8: ='1099-B Lots'!I17 -> 2600 | I8: ='1099-B Lots'!J17 -> N/A | J8: ='1099-B Lots'!L17 -> 0 | K8: ='1099-B Lots'!M17 -> N/A | O8: =IF(ISNUMBER(N8),N8,IF(ISNUMBER(I8),I8,"")) | P8: =IF(ISNUMBER(O8),H8-O8+J8,"") | Q8: term, basis, date acquired | R8: ='1099-B Lots'!R17 -> 13
A9: =T('Crypto 1099-DA'!A6) -> H | B9: =T('Crypto 1099-DA'!B6) -> ST | C9: =T('Crypto 1099-DA'!D6) -> ETHEREUM | D9: =T('Crypto 1099-DA'!E6) -> ETH | E9: ='Crypto 1099-DA'!F6 -> 1.2 | F9: ='Crypto 1099-DA'!G6 -> 45597 | G9: ='Crypto 1099-DA'!H6 -> 45748 | H9: ='Crypto 1099-DA'!I6 -> 2100 | I9: ='Crypto 1099-DA'!J6 -> N/A | J9: ='Crypto 1099-DA'!L6 -> 0 | K9: ='Crypto 1099-DA'!M6 -> N/A | O9: =IF(ISNUMBER(N9),N9,IF(ISNUMBER(I9),I9,"")) | P9: =IF(ISNUMBER(O9),H9-O9+J9,"") | Q9: basis | R9: ='Crypto 1099-DA'!R6 -> 21
C10: Total | H10: =SUM(H5:H9) -> 13065 | I10: =SUM(I5:I9) -> 1500 | J10: =SUM(J5:J9) -> 0 | K10: =SUM(K5:K9) -> 2740 | O10: =SUM(O5:O9) -> 1500 | P10: =SUM(P5:P9) -> 2740
A12: Box totals vs broker summary (tie-out only - not keyed as a summary line)
A13: Box | C13: Description | D13: # lots | H13: Proceeds | I13: Cost (1099) | J13: Wash sale | K13: Broker gain/(loss) | O13: Broker proceeds (link) | P13: Broker wash (link) | Q13: Diff proceeds | R13: Diff wash
A14: B | C14: Short-term, basis NOT reported | D14: =COUNTIF($A$5:$A$9,$A14) -> 2 | H14: =SUMIFS(H$5:H$9,$A$5:$A$9,$A14) -> 4165 | I14: =SUMIFS(I$5:I$9,$A$5:$A$9,$A14) -> 0 | J14: =SUMIFS(J$5:J$9,$A$5:$A$9,$A14) -> 0 | K14: =SUMIFS(K$5:K$9,$A$5:$A$9,$A14) -> 40 | O14: =N('1099-B Lots'!I33) -> 4165 | P14: =N('1099-B Lots'!L33) -> 0 | Q14: =ROUND(H14-O14,2) -> 0 | R14: =ROUND(J14-P14,2) -> 0
A15: E | C15: Long-term, basis NOT reported | D15: =COUNTIF($A$5:$A$9,$A15) -> 1 | H15: =SUMIFS(H$5:H$9,$A$5:$A$9,$A15) -> 4200 | I15: =SUMIFS(I$5:I$9,$A$5:$A$9,$A15) -> 1500 | J15: =SUMIFS(J$5:J$9,$A$5:$A$9,$A15) -> 0 | K15: =SUMIFS(K$5:K$9,$A$5:$A$9,$A15) -> 2700 | O15: =N('1099-B Lots'!I35) -> 4200 | P15: =N('1099-B Lots'!L35) -> 0 | Q15: =ROUND(H15-O15,2) -> 0 | R15: =ROUND(J15-P15,2) -> 0
A16: X | C16: Unknown term (term and basis from client) | D16: =COUNTIF($A$5:$A$9,$A16) -> 1 | H16: =SUMIFS(H$5:H$9,$A$5:$A$9,$A16) -> 2600 | I16: =SUMIFS(I$5:I$9,$A$5:$A$9,$A16) -> 0 | J16: =SUMIFS(J$5:J$9,$A$5:$A$9,$A16) -> 0 | K16: =SUMIFS(K$5:K$9,$A$5:$A$9,$A16) -> 0 | O16: =N('1099-B Lots'!I36) -> 2600 | P16: =N('1099-B Lots'!L36) -> 0 | Q16: =ROUND(H16-O16,2) -> 0 | R16: =ROUND(J16-P16,2) -> 0
A17: H | C17: Digital asset short-term, basis NOT reported | D17: =COUNTIF($A$5:$A$9,$A17) -> 1 | H17: =SUMIFS(H$5:H$9,$A$5:$A$9,$A17) -> 2100 | I17: =SUMIFS(I$5:I$9,$A$5:$A$9,$A17) -> 0 | J17: =SUMIFS(J$5:J$9,$A$5:$A$9,$A17) -> 0 | K17: =SUMIFS(K$5:K$9,$A$5:$A$9,$A17) -> 0 | O17: =N('Crypto 1099-DA'!I20) -> 2100 | P17: =N('Crypto 1099-DA'!L20) -> 0 | Q17: =ROUND(H17-O17,2) -> 0 | R17: =ROUND(J17-P17,2) -> 0

Sheet Crypto 1099-DA
A1: Crypto 1099-DA Lots - Sample Client - 2025 Example Brokerage
A2: Blue = keyed from the 1099 (page in Src page column). Black = formula. Calc gain = proceeds - cost + wash; Diff = calc - broker (must be 0).
A4: Box | B4: Term | C4: Ord | D4: Security | E4: CUSIP | F4: Qty | G4: Date acquired | H4: Date sold | I4: Proceeds (d) | J4: Cost basis (e) | K4: Market discount | L4: Wash sale (g) | M4: Broker gain/(loss) | N4: Calc gain/(loss) | O4: Diff | P4: Account | Q4: Notes | R4: Src page
A5: G | B5: ST | C5: N | D5: BITCOIN | E5: BTC | F5: 0.05 | G5: 45717 | H5: 45901 | I5: 5500 | J5: 4100 | K5: 0 | L5: 0 | M5: 1400 | N5: =I5-J5+L5 -> 1400 | O5: =ROUND(N5-M5,2) -> 0 | P5: 5678 | R5: 20
A6: H | B6: ST | C6: N | D6: ETHEREUM | E6: ETH | F6: 1.2 | G6: 45597 | H6: 45748 | I6: 2100 | J6: N/A | K6: 0 | L6: 0 | M6: N/A | P6: 5678 | Q6: Noncovered digital asset | R6: 21
D8: Per-lot check: sum of |Diff| (must be 0) | O8: =ROUND(SUMPRODUCT(ABS($O$5:$O$6)),2) -> 0
A10: Totals by 8949 box (sum of lots)
A11: Box | D11: Description | F11: # lots | I11: Proceeds (d) | J11: Cost basis (e) | K11: Market discount | L11: Wash sale (g) | M11: Broker gain/(loss) | N11: Calc gain/(loss)
A12: G | D12: Digital asset short-term, basis reported | F12: =COUNTIF($A$5:$A$6,$A12) -> 1 | I12: =SUMIFS($I$5:$I$6,$A$5:$A$6,$A12) -> 5500 | J12: =SUMIFS($J$5:$J$6,$A$5:$A$6,$A12) -> 4100 | K12: =SUMIFS($K$5:$K$6,$A$5:$A$6,$A12) -> 0 | L12: =SUMIFS($L$5:$L$6,$A$5:$A$6,$A12) -> 0 | M12: =SUMIFS($M$5:$M$6,$A$5:$A$6,$A12) -> 1400 | N12: =SUMIFS($N$5:$N$6,$A$5:$A$6,$A12) -> 1400
A13: H | D13: Digital asset short-term, basis NOT reported | F13: =COUNTIF($A$5:$A$6,$A13) -> 1 | I13: =SUMIFS($I$5:$I$6,$A$5:$A$6,$A13) -> 2100 | J13: =SUMIFS($J$5:$J$6,$A$5:$A$6,$A13) -> 0 | K13: =SUMIFS($K$5:$K$6,$A$5:$A$6,$A13) -> 0 | L13: =SUMIFS($L$5:$L$6,$A$5:$A$6,$A13) -> 0 | M13: =SUMIFS($M$5:$M$6,$A$5:$A$6,$A13) -> 0 | N13: =SUMIFS($N$5:$N$6,$A$5:$A$6,$A13) -> 0
A14: J | D14: Digital asset long-term, basis reported | F14: =COUNTIF($A$5:$A$6,$A14) -> 0 | I14: =SUMIFS($I$5:$I$6,$A$5:$A$6,$A14) -> 0 | J14: =SUMIFS($J$5:$J$6,$A$5:$A$6,$A14) -> 0 | K14: =SUMIFS($K$5:$K$6,$A$5:$A$6,$A14) -> 0 | L14: =SUMIFS($L$5:$L$6,$A$5:$A$6,$A14) -> 0 | M14: =SUMIFS($M$5:$M$6,$A$5:$A$6,$A14) -> 0 | N14: =SUMIFS($N$5:$N$6,$A$5:$A$6,$A14) -> 0
A15: Total | F15: =SUM(F12:F14) -> 2 | I15: =SUM(I12:I14) -> 7600 | J15: =SUM(J12:J14) -> 4100 | K15: =SUM(K12:K14) -> 0 | L15: =SUM(L12:L14) -> 0 | M15: =SUM(M12:M14) -> 1400 | N15: =SUM(N12:N14) -> 1400
A17: Broker 1099-B summary totals (keyed from the summary page)
A18: Box | D18: Source | I18: Proceeds (d) | J18: Cost basis (e) | K18: Market discount | L18: Wash sale (g) | M18: Broker gain/(loss)
A19: G | D19: 1099-B summary p.19 | I19: 5500 | J19: 4100 | K19: 0 | L19: 0 | M19: 1400
A20: H | D20: 1099-B summary p.19 | I20: 2100 | J20: N/A | K20: 0 | L20: 0 | M20: N/A
A21: J | D21: None reported | I21: 0 | J21: 0 | K21: 0 | L21: 0 | M21: 0
A23: Diff: sum of lots - broker summary (must be 0)
A24: Box | I24: Proceeds | J24: Cost | K24: Market discount | L24: Wash sale | M24: Gain/(loss)
A25: G | I25: =ROUND(I12-N(I19),2) -> 0 | J25: =ROUND(J12-N(J19),2) -> 0 | K25: =ROUND(K12-N(K19),2) -> 0 | L25: =ROUND(L12-N(L19),2) -> 0 | M25: =ROUND(M12-N(M19),2) -> 0
A26: H | I26: =ROUND(I13-N(I20),2) -> 0 | J26: =ROUND(J13-N(J20),2) -> 0 | K26: =ROUND(K13-N(K20),2) -> 0 | L26: =ROUND(L13-N(L20),2) -> 0 | M26: =ROUND(M13-N(M20),2) -> 0
A27: J | I27: =ROUND(I14-N(I21),2) -> 0 | J27: =ROUND(J14-N(J21),2) -> 0 | K27: =ROUND(K14-N(K21),2) -> 0 | L27: =ROUND(L14-N(L21),2) -> 0 | M27: =ROUND(M14-N(M21),2) -> 0
A29: Form 8949 entry lines - basis reported (linked to Summary)
A30: Box | C30: Ord | D30: Line | F30: # lots | I30: Proceeds (d) | J30: Cost basis (e) | K30: Market discount | L30: Wash sale (g) | M30: Gain/(loss) (h)
A31: G | C31: N | D31: Digital asset short-term (Box G) | F31: =COUNTIFS($A$5:$A$6,$A31,$C$5:$C$6,$C31) -> 1 | I31: =SUMIFS($I$5:$I$6,$A$5:$A$6,$A31,$C$5:$C$6,$C31) -> 5500 | J31: =SUMIFS($J$5:$J$6,$A$5:$A$6,$A31,$C$5:$C$6,$C31) -> 4100 | K31: =SUMIFS($K$5:$K$6,$A$5:$A$6,$A31,$C$5:$C$6,$C31) -> 0 | L31: =SUMIFS($L$5:$L$6,$A$5:$A$6,$A31,$C$5:$C$6,$C31) -> 0 | M31: =I31-J31+L31 -> 1400
A32: J | C32: N | D32: Digital asset long-term (Box J) | F32: =COUNTIFS($A$5:$A$6,$A32,$C$5:$C$6,$C32) -> 0 | I32: =SUMIFS($I$5:$I$6,$A$5:$A$6,$A32,$C$5:$C$6,$C32) -> 0 | J32: =SUMIFS($J$5:$J$6,$A$5:$A$6,$A32,$C$5:$C$6,$C32) -> 0 | K32: =SUMIFS($K$5:$K$6,$A$5:$A$6,$A32,$C$5:$C$6,$C32) -> 0 | L32: =SUMIFS($L$5:$L$6,$A$5:$A$6,$A32,$C$5:$C$6,$C32) -> 0 | M32: =I32-J32+L32 -> 0
A34: Subtotals by asset
D35: Asset | E35: CUSIP/ID | F35: # lots | I35: Proceeds (d) | J35: Cost basis (e) | L35: Wash sale (g) | M35: Broker gain/(loss)
D36: BITCOIN | E36: BTC | F36: =SUMPRODUCT(--($E$5:$E$6=E36)) -> 1 | I36: =SUMPRODUCT(--($E$5:$E$6=E36),$I$5:$I$6) -> 5500 | J36: =SUMPRODUCT(--($E$5:$E$6=E36),$J$5:$J$6) -> 4100 | L36: =SUMPRODUCT(--($E$5:$E$6=E36),$L$5:$L$6) -> 0 | M36: =SUMPRODUCT(--($E$5:$E$6=E36),$M$5:$M$6) -> 1400
D37: ETHEREUM | E37: ETH | F37: =SUMPRODUCT(--($E$5:$E$6=E37)) -> 1 | I37: =SUMPRODUCT(--($E$5:$E$6=E37),$I$5:$I$6) -> 2100 | J37: =SUMPRODUCT(--($E$5:$E$6=E37),$J$5:$J$6) -> 0 | L37: =SUMPRODUCT(--($E$5:$E$6=E37),$L$5:$L$6) -> 0 | M37: =SUMPRODUCT(--($E$5:$E$6=E37),$M$5:$M$6) -> 0
D38: Total | I38: =SUM(I36:I37) -> 7600 | J38: =SUM(J36:J37) -> 4100 | L38: =SUM(L36:L37) -> 0 | M38: =SUM(M36:M37) -> 1400
I39: =ROUND(I38-I15,2) -> 0 | L39: =ROUND(L38-L15,2) -> 0

Sheet Income Detail
A1: Income Detail - Sample Client - 2025 Example Brokerage
A2: Payment-level 1099-DIV/INT/OID/MISC lines (blue = keyed). Box totals are SUMPRODUCTs of the lines; Diff vs the 1099 box amount must be 0.
A4: Form | B4: Box | C4: Description | D4: Payer / security | E4: CUSIP | F4: Pay date | G4: Amount | H4: Src page
A5: DIV | B5: 1a | C5: Total ordinary dividends | D5: APPLE INC | E5: 037833100 | F5: 45701 | G5: 62.4 | H5: 4
A6: DIV | B6: 1a | C6: Total ordinary dividends | D6: SPDR S&P 500 ETF TRUST | E6: 78462F103 | F6: 45809 | G6: 18.3 | H6: 4
A7: DIV | B7: 1a | C7: Total ordinary dividends | D7: MICROSOFT CORP | E7: 594918104 | F7: 45820 | G7: 210 | H7: 4
A8: DIV | B8: 1a | C8: Total ordinary dividends | D8: VANGUARD TOTAL BOND MARKET ETF | E8: 921937835 | F8: 45870 | G8: 245.1 | H8: 4
A9: DIV | B9: 1b | C9: Qualified dividends | D9: APPLE INC | E9: 037833100 | F9: 45701 | G9: 62.4 | H9: 4
A10: DIV | B10: 1b | C10: Qualified dividends | D10: SPDR S&P 500 ETF TRUST | E10: 78462F103 | F10: 45809 | G10: 18.3 | H10: 4
A11: DIV | B11: 1b | C11: Qualified dividends | D11: MICROSOFT CORP | E11: 594918104 | F11: 45820 | G11: 210 | H11: 4
A12: DIV | B12: 2a | C12: Total capital gain distributions | D12: VANGUARD TOTAL BOND MARKET ETF | E12: 921937835 | F12: 46011 | G12: 35 | H12: 4
A13: DIV | B13: 7 | C13: Foreign tax paid | D13: SPDR S&P 500 ETF TRUST | E13: 78462F103 | F13: 45809 | G13: 4.1 | H13: 4
A14: INT | B14: 1 | C14: Interest income | D14: Cash sweep interest | G14: 88.12 | H14: 5
A15: INT | B15: 3 | C15: Interest on U.S. savings bonds & Treasury obligations | D15: US Treasury note interest | G15: 120 | H15: 5
A16: OID | B16: 8 | C16: OID on U.S. Treasury obligations | D16: Per 1099 summary page (no payment-level detail) | G16: 210 | H16: 6
A17: MISC | B17: 8 | C17: Substitute payments in lieu of dividends or interest | D17: Substitute payment - MICROSOFT | G17: 15.75 | H17: 6
A19: Totals by box: detail vs 1099 box amount (Diff must be 0)
A20: Form | B20: Box | C20: Description | D20: Destination | E20: Detail total | F20: 1099 box amount | G20: Diff | H20: Src page
A21: DIV | B21: 1a | C21: Total ordinary dividends | D21: Sch B Part II / 1040 line 3b | E21: =SUMPRODUCT(--($A$5:$A$17=$A21),--($B$5:$B$17=$B21),$G$5:$G$17) -> 535.8 | F21: 535.8 | G21: =ROUND(E21-N(F21),2) -> 0 | H21: 4
A22: DIV | B22: 1b | C22: Qualified dividends | D22: 1040 line 3a | E22: =SUMPRODUCT(--($A$5:$A$17=$A22),--($B$5:$B$17=$B22),$G$5:$G$17) -> 290.7 | F22: 290.7 | G22: =ROUND(E22-N(F22),2) -> 0 | H22: 4
A23: DIV | B23: 2a | C23: Total capital gain distributions | D23: Sch D line 13 | E23: =SUMPRODUCT(--($A$5:$A$17=$A23),--($B$5:$B$17=$B23),$G$5:$G$17) -> 35 | F23: 35 | G23: =ROUND(E23-N(F23),2) -> 0 | H23: 4
A24: DIV | B24: 7 | C24: Foreign tax paid | D24: Sch 3 line 1 or Form 1116 | E24: =SUMPRODUCT(--($A$5:$A$17=$A24),--($B$5:$B$17=$B24),$G$5:$G$17) -> 4.1 | F24: 4.1 | G24: =ROUND(E24-N(F24),2) -> 0 | H24: 4
A25: INT | B25: 1 | C25: Interest income | D25: Sch B Part I / 1040 line 2b | E25: =SUMPRODUCT(--($A$5:$A$17=$A25),--($B$5:$B$17=$B25),$G$5:$G$17) -> 88.12 | F25: 88.12 | G25: =ROUND(E25-N(F25),2) -> 0 | H25: 4
A26: INT | B26: 3 | C26: Interest on U.S. savings bonds & Treasury obligations | D26: Sch B / 1040 line 2b; state subtraction | E26: =SUMPRODUCT(--($A$5:$A$17=$A26),--($B$5:$B$17=$B26),$G$5:$G$17) -> 120 | F26: 120 | G26: =ROUND(E26-N(F26),2) -> 0 | H26: 4
A27: OID | B27: 8 | C27: OID on U.S. Treasury obligations | D27: Sch B; state subtraction | E27: =SUMPRODUCT(--($A$5:$A$17=$A27),--($B$5:$B$17=$B27),$G$5:$G$17) -> 210 | F27: 210 | G27: =ROUND(E27-N(F27),2) -> 0 | H27: 6
A28: MISC | B28: 8 | C28: Substitute payments in lieu of dividends or interest | D28: Sch 1 line 8z (ordinary, NOT qualified) | E28: =SUMPRODUCT(--($A$5:$A$17=$A28),--($B$5:$B$17=$B28),$G$5:$G$17) -> 15.75 | F28: 15.75 | G28: =ROUND(E28-N(F28),2) -> 0 | H28: 4
A30: Supplemental / non-reportable items and Section 1256
A31: Category | C31: Description | D31: Destination | E31: Amount | H31: Src page
A32: margin_interest | C32: Margin interest paid | D32: Form 4952 (investment interest) | E32: 312.45 | H32: 30
A33: adr_fee | C33: ADR custody fees | D33: Not deductible | E33: 6 | H33: 30
A34: section_1256 | C34: Aggregate profit/(loss) on contracts (box 11) | D34: Form 6781 | E34: -1250 | H34: 18
A36: State: U.S. Treasury / direct federal obligation subtraction
C37: Security | D37: CUSIP | E37: % from 1099 | F37: Fund ordinary dividends | G37: State subtraction | H37: Src page
C38: VANGUARD TOTAL BOND MARKET ETF | D38: 921937835 | E38: 0.4215 | F38: =SUMPRODUCT(--($A$5:$A$17="DIV"),--($B$5:$B$17="1a"),--($E$5:$E$17=$D38),$G$5:$G$17) -> 245.1 | G38: =ROUND(E38*F38,2) -> 103.31 | H38: 31
C39: 1099-INT box 3 (Treasury interest) | G39: =E26 -> 120
C40: 1099-OID box 8 (Treasury OID) | G40: =E27 -> 210
C41: Total state subtraction | G41: =SUM(G38:G40) -> 433.31

Sheet Flags & Questions
A1: Flags & Questions - Sample Client - 2025
A2: Amounts are computed by the program from the 1099 data. Update Status as items are resolved.
A4: # | B4: Category | C4: Issue / question | D4: Amount | E4: Status
A5: 1 | B5: Wash sales | C5: Broker tracks only same-account, identical-CUSIP wash sales. Ask about purchases in IRAs (loss permanently disallowed), spouse's accounts, other brokers and options on the same securities. | D5: 850 | E5: Open
A6: 2 | B6: Wash sales | C6: 1 wash line(s) have a disallowed amount larger than the line's own loss (broker aggregation). Reported as the broker computed. | D6: 350 | E6: Open
A7: 3 | B7: Unknown term | C7: 1 unknown-term lot(s): holding period AND basis must come from the client before entry. | D7: 2600 | E7: Open
A8: 4 | B8: Noncovered basis | C8: Box B: 1 lot(s) with no basis on the 1099; client must supply basis and date acquired. | D8: 4125 | E8: Open
A9: 5 | B9: Noncovered | C9: Box B: 2 lot(s) basis not reported to IRS: enter each lot individually and verify basis with the client. | D9: 4165 | E9: Open
A10: 6 | B10: Noncovered | C10: Box E: 1 lot(s) basis not reported to IRS: enter each lot individually and verify basis with the client. | D10: 4200 | E10: Open
A11: 7 | B11: Noncovered basis | C11: Box H: 1 lot(s) with no basis on the 1099; client must supply basis and date acquired. | D11: 2100 | E11: Open
A12: 8 | B12: Noncovered | C12: Box H: 1 lot(s) basis not reported to IRS: enter each lot individually and verify basis with the client. | D12: 2100 | E12: Open
A13: 9 | B13: Digital assets | C13: Noncovered 1099-DA lots (Box H/K): basis comes from broker records only; request support. | E13: Open
A14: 10 | B14: Digital assets | C14: Digital asset transactions present: answer YES to the Form 1040 digital asset question. | E14: Open
A15: 11 | B15: Zero basis | C15: ABC CORP CVR: CVR with zero/no basis; confirm basis allocation with the client. | D15: 40 | E15: Open
A16: 12 | B16: Substitute payments | C16: 1099-MISC box 8 substitute payments are ordinary income, not qualified dividends. | D16: 15.75 | E16: Open
A17: 13 | B17: Qualified dividends | C17: Holding-period screen: lots held 60 days or less straddle qualified dividend payments (APPLE INC, SPDR S&P 500 ETF TRUST). Ex-date is not on the 1099; ask whether other shares were held through year-end. | D17: 80.7 | E17: Open
A18: 14 | B18: Section 1256 | C18: Section 1256 aggregate profit/(loss) goes to Form 6781 (60/40), not Form 8949. | D18: -1250 | E18: Open
A19: 15 | B19: Margin interest | C19: Margin interest goes to Form 4952: check net investment income and ask whether the client elects to treat qualified dividends/gains as investment income. | D19: 312.45 | E19: Open
A20: 16 | B20: Fees | C20: ADR and other investment fees are not deductible. | D20: 6 | E20: Open
A21: 17 | B21: State | C21: U.S. Treasury / direct federal obligation interest is a state subtraction in most states (including Colorado). | D21: 433.31 | E21: Open
A22: 18 | B22: Completeness | C22: Confirm there are no separate joint, retirement or other-broker 1099s for this client. | E22: Open
